<?xml version="1.0" encoding="utf-8"?>
<robot name="ballbot_v1" xmlns:xacro="http://ros.org/wiki/xacro">

  <xacro:arg name="is_ignition" default="true"/>

  <link name="base_footprint"/>

  <joint name="base_joint" type="fixed">
    <parent link="base_footprint"/>
    <child link="base_link"/>
    <origin xyz="0 0 0" rpy="0 0 0"/>
  </joint>

  <link name="base_link">
    <inertial>
      <origin xyz="-0.0222862748260381 -0.0589079641755681 0.342852950412891" rpy="0 0 0" />
      <mass value="9.07275285614964" />
      <inertia ixx="0.0571612867174266" ixy="-0.000456298503903011" ixz="0.00199038340986464" iyy="0.0565565637552512" iyz="0.00626888807442685" izz="0.0280267125691441" />
    </inertial>
    <visual>
      <origin xyz="0 0 0" rpy="0 0 0" />
      <geometry>
        <mesh filename="package://gp_description/meshes/base_link.STL" />
      </geometry>
      <material name="white">
        <color rgba="1 1 1 1" />
      </material>
    </visual>
    <collision>
      <origin xyz="0 0 0" rpy="0 0 0" />
      <geometry>
        <mesh filename="package://gp_description/meshes/base_link.STL" />
      </geometry>
    </collision>
  </link>

  <link name="Sphere">
    <inertial>
      <origin xyz="-1.3878E-17 0 2.2204E-16" rpy="0 0 0" />
      <mass value="8.1812" />
      <inertia ixx="0.051133" ixy="-1.7382E-18" ixz="-5.0688E-18" iyy="0.051133" iyz="-1.3193E-18" izz="0.051133" />
    </inertial>
    <visual>
      <origin xyz="0 0 0" rpy="0 0 0" />
      <geometry>
        <mesh filename="package://gp_description/meshes/Sphere.STL" />
      </geometry>
      <material name="blue">
        <color rgba="0.2 0.4 0.8 1" />
      </material>
    </visual>
    <collision>
      <origin xyz="0 0 0" rpy="0 0 0" />
      <geometry>
        <sphere radius="0.125"/> 
      </geometry>
    </collision>
  </link>

  <joint name="sphere_joint" type="continuous">
    <origin xyz="0 0 -0.17" rpy="0 0 0" /> <parent link="base_link" />
    <child link="Sphere" />
    <axis xyz="-0.054724 0.6568 0.75207" />
    <limit effort="70" velocity="70" />
  </joint>
  
  <link name="wheel1">
    <inertial>
      <origin xyz="0.0095356 -1.7869E-05 -8.3451E-05" rpy="0 0 0" />
      <mass value="0.095114" />
      <inertia ixx="4.6565E-05" ixy="6.0923E-12" ixz="-8.6148E-12" iyy="2.5259E-05" iyz="3.0906E-10" izz="2.5259E-05" />
    </inertial>
    <visual>
      <origin xyz="0 0 0" rpy="0 0 0" />
      <geometry>
        <mesh filename="package://gp_description/meshes/wheel1.STL" />
      </geometry>
      <material name="grey">
        <color rgba="0.5 0.5 0.5 1" />
      </material>
    </visual>
    <collision>
      <origin xyz="0 0 0" rpy="1.5708 0 0" />
      <geometry>
        <cylinder radius="0.05" length="0.03"/>
      </geometry>
    </collision>
  </link>

  <joint name="wheel1_joint" type="continuous">
    <origin xyz="-0.13164 0.042441 0.10792" rpy="0.4894 -0.72885 -0.67456" />
    <parent link="base_link" />
    <child link="wheel1" />
    <axis xyz="1 0 0" />
    <limit effort="70" velocity="70" />
    <dynamics damping="0.1" friction="0.1"/>
  </joint>

  <link name="wheel2">
    <inertial>
      <origin xyz="0.00084987 -0.0051411 0.0079863" rpy="0 0 0" />
      <mass value="0.095114" />
      <inertia ixx="2.5418E-05" ixy="-1.0047E-06" ixz="1.5323E-06" iyy="3.1619E-05" iyz="-9.6981E-06" izz="4.0045E-05" />
    </inertial>
    <visual>
      <origin xyz="0 0 0" rpy="0 0 0" />
      <geometry>
        <mesh filename="package://gp_description/meshes/wheel2.STL" />
      </geometry>
      <material name="grey">
        <color rgba="0.5 0.5 0.5 1" />
      </material>
    </visual>
    <collision>
      <origin xyz="0 0 0" rpy="1.5708 0 0" />
      <geometry>
        <cylinder radius="0.05" length="0.03"/>
      </geometry>
    </collision>
  </link>

  <joint name="wheel2_joint" type="continuous">
    <origin xyz="0.002137 -0.15885 0.074451" rpy="0 0 3.1416" />
    <parent link="base_link" />
    <child link="wheel2" />
    <axis xyz="0.086321 -0.54639 0.83307" />
    <limit effort="70" velocity="70" />
    <dynamics damping="0.1" friction="0.1"/>
  </joint>

  <link name="wheel3">
    <inertial>
      <origin xyz="0.0095356 -1.7869E-05 -8.3451E-05" rpy="0 0 0" />
      <mass value="0.095114" />
      <inertia ixx="4.6565E-05" ixy="6.0923E-12" ixz="-8.6148E-12" iyy="2.5259E-05" iyz="3.0906E-10" izz="2.5259E-05" />
    </inertial>
    <visual>
      <origin xyz="0 0 0" rpy="0 0 0" />
      <geometry>
        <mesh filename="package://gp_description/meshes/wheel3.STL" />
      </geometry>
      <material name="grey">
        <color rgba="0.5 0.5 0.5 1" />
      </material>
    </visual>
    <collision>
      <origin xyz="0 0 0" rpy="1.5708 0 0" />
      <geometry>
        <cylinder radius="0.05" length="0.03"/>
      </geometry>
    </collision>
  </link>

  <joint name="wheel3_joint" type="continuous">
    <origin xyz="0.11108 0.052344 0.12536" rpy="-0.43356 -0.6093 -2.4614" />
    <parent link="base_link" />
    <child link="wheel3" />
    <axis xyz="1 0 0" />
    <limit effort="70" velocity="70" />
    <dynamics damping="0.1" friction="0.1"/>
  </joint>

  <link name="imu_link"/>
  <joint name="imu_joint" type="fixed">
    <parent link="base_link"/>
    <child link="imu_link"/>
    <origin xyz="0 0 0.1" rpy="0 0 0"/> 
  </joint>

  <link name="laser_link"/>
  <joint name="laser_joint" type="fixed">
    <parent link="base_link"/>
    <child link="laser_link"/>
    <origin xyz="0 0 0.25" rpy="0 0 0"/> 
  </joint>

  <ros2_control name="GazeboSystem" type="system">
    <hardware>
      <plugin>gz_ros2_control/GazeboSimSystem</plugin>
    </hardware>
    <joint name="wheel1_joint">
      <command_interface name="velocity"/>
      <state_interface name="position"/>
      <state_interface name="velocity"/>
    </joint>
    <joint name="wheel2_joint">
      <command_interface name="velocity"/>
      <state_interface name="position"/>
      <state_interface name="velocity"/>
    </joint>
    <joint name="wheel3_joint">
      <command_interface name="velocity"/>
      <state_interface name="position"/>
      <state_interface name="velocity"/>
    </joint>
  </ros2_control>

  <gazebo>
    <plugin filename="gz_ros2_control-system" name="gz_ros2_control::GazeboSimROS2ControlPlugin">
      <parameters>$(find gp_description)/config/controllers.yaml</parameters>
    </plugin>
  </gazebo>

  <gazebo reference="imu_link">
    <sensor name="imu_sensor" type="imu">
      <always_on>true</always_on>
      <update_rate>100</update_rate>
      <topic>imu</topic>
      <plugin filename="libgz-sim-imu-system.so" name="gz::sim::systems::Imu"/>
    </sensor>
  </gazebo>

  <gazebo reference="laser_link">
    <sensor name="lidar" type="gpu_lidar">
      <always_on>true</always_on>
      <update_rate>10</update_rate>
      <topic>scan</topic>
      <ray>
        <scan>
          <horizontal>
            <samples>360</samples>
            <resolution>1.0</resolution>
            <min_angle>-3.14159</min_angle>
            <max_angle>3.14159</max_angle>
          </horizontal>
        </scan>
        <range>
          <min>0.12</min>
          <max>10.0</max>
        </range>
      </ray>
      <plugin filename="libgz-sim-sensors-system.so" name="gz::sim::systems::Sensors"/>
    </sensor>
  </gazebo>

</robot>